Workbook

Sheet Read Me
A1: CIS Critical Security Controls v8.1 — IG3 mapped to Microsoft / Azure / M365
A3: Scope
A4: Implementation Group 3 includes every safeguard in CIS Controls v8.1, so all 18 Controls / 153 Safeguards are mapped. IG1/IG2 columns show which safeguards also belong to the lower groups, so the same sheet can be filtered to IG1 or IG2.
A6: How to use
A7: 1. 'CIS IG3 Mapping' — one row per safeguard: CIS attributes, Microsoft coverage rating, Microsoft services, what to implement, evidence for auditors, licensing notes and related Microsoft Cloud Security Benchmark (MCSB) controls.
A8: 2. Yellow columns (Status, Owner, Target date, Notes) are for you to fill in. Status uses a dropdown: Not started / Planned / In progress / Implemented / Risk accepted / Not applicable. Example: Status = In progress, Owner = Endpoint team, Target date = 2026-12-31, Notes = 'ASR rules in audit; enforce after pilot'.
A9: 3. 'Summary' — counts by Control and coverage rating, plus your implementation progress (calculated from the Status column).
A11: Coverage rating (Microsoft tooling)
A12: Native — Microsoft/Azure/M365 tooling can implement the safeguard technically end-to-end with the right licences.
A13: Partial — Microsoft tooling covers a meaningful part but you need process work, non-Microsoft devices/vendors, or a third party (e.g. pentesters, NAC, physical network gear).
A14: Process — the safeguard is primarily a documented policy/process; Microsoft tools only host evidence or support it.
A16: Important caveats
... A20: • Purview Compliance Manager offers regulatory templates for many standards; check its regulations list for a CIS Controls template to track this programme with continuous assessment.

Sheet Summary
A1: CIS v8.1 IG3 → Microsoft coverage summary
A2: All figures are formulas over the 'CIS IG3 Mapping' sheet and update as you fill in Status.
A4: Control | B4: Control Title | C4: Safeguards | D4: IG1 | E4: IG2 | F4: Native | G4: Partial | H4: Process | I4: Implemented | J4: In progress / Planned | K4: Not started / blank | L4: % Implemented
A5: 1 | B5: Inventory and Control of Enterprise Assets | C5: =COUNTIF('CIS IG3 Mapping'!$A$2:$A$154,A5) -> 5 | D5: =COUNTIFS('CIS IG3 Mapping'!$A$2:$A$154,A5,'CIS IG3 Mapping'!$G$2:$G$154,"✓") -> 2 | E5: =COUNTIFS('CIS IG3 Mapping'!$A$2:$A$154,A5,'CIS IG3 Mapping'!$H$2:$H$154,"✓") -> 4 | F5: =COUNTIFS('CIS IG3 Mapping'!$A$2:$A$154,A5,'CIS IG3 Mapping'!$J$2:$J$154,"Native") -> 4 | G5: =COUNTIFS('CIS IG3 Mapping'!$A$2:$A$154,A5,'CIS IG3 Mapping'!$J$2:$J$154,"Partial") -> 1 | H5: =COUNTIFS('CIS IG3 Mapping'!$A$2:$A$154,A5,'CIS IG3 Mapping'!$J$2:$J$154,"Process") -> 0 | I5: =COUNTIFS('CIS IG3 Mapping'!$A$2:$A$154,A5,'CIS IG3 Mapping'!$P$2:$P$154,"Implemented") -> 0 | J5: =COUNTIFS('CIS IG3 Mapping'!$A$2:$A$154,A5,'CIS IG3 Mapping'!$P$2:$P$154,"In progress")+COUNTIFS('CIS IG3 Mapping'!$A$2:$A$154,A5,'CIS IG3 Mapping'!$P$2:$P$154,"Planned") -> 0 | K5: =COUNTIFS('CIS IG3 Mapping'!$A$2:$A$154,A5,'CIS IG3 Mapping'!$P$2:$P$154,"Not started")+COUNTIFS('CIS IG3 Mapping'!$A$2:$A$154,A5,'CIS IG3 Mapping'!$P$2:$P$154,"") -> 5 | L5: =IF((C5-COUNTIFS('CIS IG3 Mapping'!$A$2:$A$154,A5,'CIS IG3 Mapping'!$P$2:$P$154,"Not applicable"))=0,0,I5/(C5-COUNTIFS('CIS IG3 Mapping'!$A$2:$A$154,A5,'CIS IG3 Mapping'!$P$2:$P$154,"Not applicable"))) -> 0
A6: 2 | B6: Inventory and Control of Software Assets | C6: =COUNTIF('CIS IG3 Mapping'!$A$2:$A$154,A6) -> 7 | D6: =COUNTIFS('CIS IG3 Mapping'!$A$2:$A$154,A6,'CIS IG3 Mapping'!$G$2:$G$154,"✓") -> 3 | E6: =COUNTIFS('CIS IG3 Mapping'!$A$2:$A$154,A6,'CIS IG3 Mapping'!$H$2:$H$154,"✓") -> 6 | F6: =COUNTIFS('CIS IG3 Mapping'!$A$2:$A$154,A6,'CIS IG3 Mapping'!$J$2:$J$154,"Native") -> 7 | G6: =COUNTIFS('CIS IG3 Mapping'!$A$2:$A$154,A6,'CIS IG3 Mapping'!$J$2:$J$154,"Partial") -> 0 | H6: =COUNTIFS('CIS IG3 Mapping'!$A$2:$A$154,A6,'CIS IG3 Mapping'!$J$2:$J$154,"Process") -> 0 | I6: =COUNTIFS('CIS IG3 Mapping'!$A$2:$A$154,A6,'CIS IG3 Mapping'!$P$2:$P$154,"Implemented") -> 0 | J6: =COUNTIFS('CIS IG3 Mapping'!$A$2:$A$154,A6,'CIS IG3 Mapping'!$P$2:$P$154,"In progress")+COUNTIFS('CIS IG3 Mapping'!$A$2:$A$154,A6,'CIS IG3 Mapping'!$P$2:$P$154,"Planned") -> 0 | K6: =COUNTIFS('CIS IG3 Mapping'!$A$2:$A$154,A6,'CIS IG3 Mapping'!$P$2:$P$154,"Not started")+COUNTIFS('CIS IG3 Mapping'!$A$2:$A$154,A6,'CIS IG3 Mapping'!$P$2:$P$154,"") -> 7 | L6: =IF((C6-COUNTIFS('CIS IG3 Mapping'!$A$2:$A$154,A6,'CIS IG3 Mapping'!$P$2:$P$154,"Not applicable"))=0,0,I6/(C6-COUNTIFS('CIS IG3 Mapping'!$A$2:$A$154,A6,'CIS IG3 Mapping'!$P$2:$P$154,"Not applicable"))) -> 0
A7: 3 | B7: Data Protection | C7: =COUNTIF('CIS IG3 Mapping'!$A$2:$A$154,A7) -> 14 | D7: =COUNTIFS('CIS IG3 Mapping'!$A$2:$A$154,A7,'CIS IG3 Mapping'!$G$2:$G$154,"✓") -> 6 | E7: =COUNTIFS('CIS IG3 Mapping'!$A$2:$A$154,A7,'CIS IG3 Mapping'!$H$2:$H$154,"✓") -> 12 | F7: =COUNTIFS('CIS IG3 Mapping'!$A$2:$A$154,A7,'CIS IG3 Mapping'!$J$2:$J$154,"Native") -> 11 | G7: =COUNTIFS('CIS IG3 Mapping'!$A$2:$A$154,A7,'CIS IG3 Mapping'!$J$2:$J$154,"Partial") -> 2 | H7: =COUNTIFS('CIS IG3 Mapping'!$A$2:$A$154,A7,'CIS IG3 Mapping'!$J$2:$J$154,"Process") -> 1 | I7: =COUNTIFS('CIS IG3 Mapping'!$A$2:$A$154,A7,'CIS IG3 Mapping'!$P$2:$P$154,"Implemented") -> 0 | J7: =COUNTIFS('CIS IG3 Mapping'!$A$2:$A$154,A7,'CIS IG3 Mapping'!$P$2:$P$154,"In progress")+COUNTIFS('CIS IG3 Mapping'!$A$2:$A$154,A7,'CIS IG3 Mapping'!$P$2:$P$154,"Planned") -> 0 | K7: =COUNTIFS('CIS IG3 Mapping'!$A$2:$A$154,A7,'CIS IG3 Mapping'!$P$2:$P$154,"Not started")+COUNTIFS('CIS IG3 Mapping'!$A$2:$A$154,A7,'CIS IG3 Mapping'!$P$2:$P$154,"") -> 14 | L7: =IF((C7-COUNTIFS('CIS IG3 Mapping'!$A$2:$A$154,A7,'CIS IG3 Mapping'!$P$2:$P$154,"Not applicable"))=0,0,I7/(C7-COUNTIFS('CIS IG3 Mapping'!$A$2:$A$154,A7,'CIS IG3 Mapping'!$P$2:$P$154,"Not applicable"))) -> 0
A8: 4 | B8: Secure Configuration of Enterprise Assets and Software | C8: =COUNTIF('CIS IG3 Mapping'!$A$2:$A$154,A8) -> 12 | D8: =COUNTIFS('CIS IG3 Mapping'!$A$2:$A$154,A8,'CIS IG3 Mapping'!$G$2:$G$154,"✓") -> 7 | E8: =COUNTIFS('CIS IG3 Mapping'!$A$2:$A$154,A8,'CIS IG3 Mapping'!$H$2:$H$154,"✓") -> 11 | F8: =COUNTIFS('CIS IG3 Mapping'!$A$2:$A$154,A8,'CIS IG3 Mapping'!$J$2:$J$154,"Native") -> 11 | G8: =COUNTIFS('CIS IG3 Mapping'!$A$2:$A$154,A8,'CIS IG3 Mapping'!$J$2:$J$154,"Partial") -> 1 | H8: =COUNTIFS('CIS IG3 Mapping'!$A$2:$A$154,A8,'CIS IG3 Mapping'!$J$2:$J$154,"Process") -> 0 | I8: =COUNTIFS('CIS IG3 Mapping'!$A$2:$A$154,A8,'CIS IG3 Mapping'!$P$2:$P$154,"Implemented") -> 0 | J8: =COUNTIFS('CIS IG3 Mapping'!$A$2:$A$154,A8,'CIS IG3 Mapping'!$P$2:$P$154,"In progress")+COUNTIFS('CIS IG3 Mapping'!$A$2:$A$154,A8,'CIS IG3 Mapping'!$P$2:$P$154,"Planned") -> 0 | K8: =COUNTIFS('CIS IG3 Mapping'!$A$2:$A$154,A8,'CIS IG3 Mapping'!$P$2:$P$154,"Not started")+COUNTIFS('CIS IG3 Mapping'!$A$2:$A$154,A8,'CIS IG3 Mapping'!$P$2:$P$154,"") -> 12 | L8: =IF((C8-COUNTIFS('CIS IG3 Mapping'!$A$2:$A$154,A8,'CIS IG3 Mapping'!$P$2:$P$154,"Not applicable"))=0,0,I8/(C8-COUNTIFS('CIS IG3 Mapping'!$A$2:$A$154,A8,'CIS IG3 Mapping'!$P$2:$P$154,"Not applicable"))) -> 0
A9: 5 | B9: Account Management | C9: =COUNTIF('CIS IG3 Mapping'!$A$2:$A$154,A9) -> 6 | D9: =COUNTIFS('CIS IG3 Mapping'!$A$2:$A$154,A9,'CIS IG3 Mapping'!$G$2:$G$154,"✓") -> 4 | E9: =COUNTIFS('CIS IG3 Mapping'!$A$2:$A$154,A9,'CIS IG3 Mapping'!$H$2:$H$154,"✓") -> 6 | F9: =COUNTIFS('CIS IG3 Mapping'!$A$2:$A$154,A9,'CIS IG3 Mapping'!$J$2:$J$154,"Native") -> 6 | G9: =COUNTIFS('CIS IG3 Mapping'!$A$2:$A$154,A9,'CIS IG3 Mapping'!$J$2:$J$154,"Partial") -> 0 | H9: =COUNTIFS('CIS IG3 Mapping'!$A$2:$A$154,A9,'CIS IG3 Mapping'!$J$2:$J$154,"Process") -> 0 | I9: =COUNTIFS('CIS IG3 Mapping'!$A$2:$A$154,A9,'CIS IG3 Mapping'!$P$2:$P$154,"Implemented") -> 0 | J9: =COUNTIFS('CIS IG3 Mapping'!$A$2:$A$154,A9,'CIS IG3 Mapping'!$P$2:$P$154,"In progress")+COUNTIFS('CIS IG3 Mapping'!$A$2:$A$154,A9,'CIS IG3 Mapping'!$P$2:$P$154,"Planned") -> 0 | K9: =COUNTIFS('CIS IG3 Mapping'!$A$2:$A$154,A9,'CIS IG3 Mapping'!$P$2:$P$154,"Not started")+COUNTIFS('CIS IG3 Mapping'!$A$2:$A$154,A9,'CIS IG3 Mapping'!$P$2:$P$154,"") -> 6 | L9: =IF((C9-COUNTIFS('CIS IG3 Mapping'!$A$2:$A$154,A9,'CIS IG3 Mapping'!$P$2:$P$154,"Not applicable"))=0,0,I9/(C9-COUNTIFS('CIS IG3 Mapping'!$A$2:$A$154,A9,'CIS IG3 Mapping'!$P$2:$P$154,"Not applicable"))) -> 0
A10: 6 | B10: Access Control Management | C10: =COUNTIF('CIS IG3 Mapping'!$A$2:$A$154,A10) -> 8 | D10: =COUNTIFS('CIS IG3 Mapping'!$A$2:$A$154,A10,'CIS IG3 Mapping'!$G$2:$G$154,"✓") -> 5 | E10: =COUNTIFS('CIS IG3 Mapping'!$A$2:$A$154,A10,'CIS IG3 Mapping'!$H$2:$H$154,"✓") -> 7 | F10: =COUNTIFS('CIS IG3 Mapping'!$A$2:$A$154,A10,'CIS IG3 Mapping'!$J$2:$J$154,"Native") -> 7 | G10: =COUNTIFS('CIS IG3 Mapping'!$A$2:$A$154,A10,'CIS IG3 Mapping'!$J$2:$J$154,"Partial") -> 1 | H10: =COUNTIFS('CIS IG3 Mapping'!$A$2:$A$154,A10,'CIS IG3 Mapping'!$J$2:$J$154,"Process") -> 0 | I10: =COUNTIFS('CIS IG3 Mapping'!$A$2:$A$154,A10,'CIS IG3 Mapping'!$P$2:$P$154,"Implemented") -> 0 | J10: =COUNTIFS('CIS IG3 Mapping'!$A$2:$A$154,A10,'CIS IG3 Mapping'!$P$2:$P$154,"In progress")+COUNTIFS('CIS IG3 Mapping'!$A$2:$A$154,A10,'CIS IG3 Mapping'!$P$2:$P$154,"Planned") -> 0 | K10: =COUNTIFS('CIS IG3 Mapping'!$A$2:$A$154,A10,'CIS IG3 Mapping'!$P$2:$P$154,"Not started")+COUNTIFS('CIS IG3 Mapping'!$A$2:$A$154,A10,'CIS IG3 Mapping'!$P$2:$P$154,"") -> 8 | L10: =IF((C10-COUNTIFS('CIS IG3 Mapping'!$A$2:$A$154,A10,'CIS IG3 Mapping'!$P$2:$P$154,"Not applicable"))=0,0,I10/(C10-COUNTIFS('CIS IG3 Mapping'!$A$2:$A$154,A10,'CIS IG3 Mapping'!$P$2:$P$154,"Not applicable"))) -> 0
A11: 7 | B11: Continuous Vulnerability Management | C11: =COUNTIF('CIS IG3 Mapping'!$A$2:$A$154,A11) -> 7 | D11: =COUNTIFS('CIS IG3 Mapping'!$A$2:$A$154,A11,'CIS IG3 Mapping'!$G$2:$G$154,"✓") -> 4 | E11: =COUNTIFS('CIS IG3 Mapping'!$A$2:$A$154,A11,'CIS IG3 Mapping'!$H$2:$H$154,"✓") -> 7 | F11: =COUNTIFS('CIS IG3 Mapping'!$A$2:$A$154,A11,'CIS IG3 Mapping'!$J$2:$J$154,"Native") -> 5 | G11: =COUNTIFS('CIS IG3 Mapping'!$A$2:$A$154,A11,'CIS IG3 Mapping'!$J$2:$J$154,"Partial") -> 1 | H11: =COUNTIFS('CIS IG3 Mapping'!$A$2:$A$154,A11,'CIS IG3 Mapping'!$J$2:$J$154,"Process") -> 1 | I11: =COUNTIFS('CIS IG3 Mapping'!$A$2:$A$154,A11,'CIS IG3 Mapping'!$P$2:$P$154,"Implemented") -> 0 | J11: =COUNTIFS('CIS IG3 Mapping'!$A$2:$A$154,A11,'CIS IG3 Mapping'!$P$2:$P$154,"In progress")+COUNTIFS('CIS IG3 Mapping'!$A$2:$A$154,A11,'CIS IG3 Mapping'!$P$2:$P$154,"Planned") -> 0 | K11: =COUNTIFS('CIS IG3 Mapping'!$A$2:$A$154,A11,'CIS IG3 Mapping'!$P$2:$P$154,"Not started")+COUNTIFS('CIS IG3 Mapping'!$A$2:$A$154,A11,'CIS IG3 Mapping'!$P$2:$P$154,"") -> 7 | L11: =IF((C11-COUNTIFS('CIS IG3 Mapping'!$A$2:$A$154,A11,'CIS IG3 Mapping'!$P$2:$P$154,"Not applicable"))=0,0,I11/(C11-COUNTIFS('CIS IG3 Mapping'!$A$2:$A$154,A11,'CIS IG3 Mapping'!$P$2:$P$154,"Not applicable"))) -> 0
A12: 8 | B12: Audit Log Management | C12: =COUNTIF('CIS IG3 Mapping'!$A$2:$A$154,A12) -> 12 | D12: =COUNTIFS('CIS IG3 Mapping'!$A$2:$A$154,A12,'CIS IG3 Mapping'!$G$2:$G$154,"✓") -> 3 | E12: =COUNTIFS('CIS IG3 Mapping'!$A$2:$A$154,A12,'CIS IG3 Mapping'!$H$2:$H$154,"✓") -> 11 | F12: =COUNTIFS('CIS IG3 Mapping'!$A$2:$A$154,A12,'CIS IG3 Mapping'!$J$2:$J$154,"Native") -> 11 | G12: =COUNTIFS('CIS IG3 Mapping'!$A$2:$A$154,A12,'CIS IG3 Mapping'!$J$2:$J$154,"Partial") -> 0 | H12: =COUNTIFS('CIS IG3 Mapping'!$A$2:$A$154,A12,'CIS IG3 Mapping'!$J$2:$J$154,"Process") -> 1 | I12: =COUNTIFS('CIS IG3 Mapping'!$A$2:$A$154,A12,'CIS IG3 Mapping'!$P$2:$P$154,"Implemented") -> 0 | J12: =COUNTIFS('CIS IG3 Mapping'!$A$2:$A$154,A12,'CIS IG3 Mapping'!$P$2:$P$154,"In progress")+COUNTIFS('CIS IG3 Mapping'!$A$2:$A$154,A12,'CIS IG3 Mapping'!$P$2:$P$154,"Planned") -> 0 | K12: =COUNTIFS('CIS IG3 Mapping'!$A$2:$A$154,A12,'CIS IG3 Mapping'!$P$2:$P$154,"Not started")+COUNTIFS('CIS IG3 Mapping'!$A$2:$A$154,A12,'CIS IG3 Mapping'!$P$2:$P$154,"") -> 12 | L12: =IF((C12-COUNTIFS('CIS IG3 Mapping'!$A$2:$A$154,A12,'CIS IG3 Mapping'!$P$2:$P$154,"Not applicable"))=0,0,I12/(C12-COUNTIFS('CIS IG3 Mapping'!$A$2:$A$154,A12,'CIS IG3 Mapping'!$P$2:$P$154,"Not applicable"))) -> 0
A13: 9 | B13: Email and Web Browser Protections | C13: =COUNTIF('CIS IG3 Mapping'!$A$2:$A$154,A13) -> 7 | D13: =COUNTIFS('CIS IG3 Mapping'!$A$2:$A$154,A13,'CIS IG3 Mapping'!$G$2:$G$154,"✓") -> 2 | E13: =COUNTIFS('CIS IG3 Mapping'!$A$2:$A$154,A13,'CIS IG3 Mapping'!$H$2:$H$154,"✓") -> 6 | F13: =COUNTIFS('CIS IG3 Mapping'!$A$2:$A$154,A13,'CIS IG3 Mapping'!$J$2:$J$154,"Native") -> 7 | G13: =COUNTIFS('CIS IG3 Mapping'!$A$2:$A$154,A13,'CIS IG3 Mapping'!$J$2:$J$154,"Partial") -> 0 | H13: =COUNTIFS('CIS IG3 Mapping'!$A$2:$A$154,A13,'CIS IG3 Mapping'!$J$2:$J$154,"Process") -> 0 | I13: =COUNTIFS('CIS IG3 Mapping'!$A$2:$A$154,A13,'CIS IG3 Mapping'!$P$2:$P$154,"Implemented") -> 0 | J13: =COUNTIFS('CIS IG3 Mapping'!$A$2:$A$154,A13,'CIS IG3 Mapping'!$P$2:$P$154,"In progress")+COUNTIFS('CIS IG3 Mapping'!$A$2:$A$154,A13,'CIS IG3 Mapping'!$P$2:$P$154,"Planned") -> 0 | K13: =COUNTIFS('CIS IG3 Mapping'!$A$2:$A$154,A13,'CIS IG3 Mapping'!$P$2:$P$154,"Not started")+COUNTIFS('CIS IG3 Mapping'!$A$2:$A$154,A13,'CIS IG3 Mapping'!$P$2:$P$154,"") -> 7 | L13: =IF((C13-COUNTIFS('CIS IG3 Mapping'!$A$2:$A$154,A13,'CIS IG3 Mapping'!$P$2:$P$154,"Not applicable"))=0,0,I13/(C13-COUNTIFS('CIS IG3 Mapping'!$A$2:$A$154,A13,'CIS IG3 Mapping'!$P$2:$P$154,"Not applicable"))) -> 0
A14: 10 | B14: Malware Defenses | C14: =COUNTIF('CIS IG3 Mapping'!$A$2:$A$154,A14) -> 7 | D14: =COUNTIFS('CIS IG3 Mapping'!$A$2:$A$154,A14,'CIS IG3 Mapping'!$G$2:$G$154,"✓") -> 3 | E14: =COUNTIFS('CIS IG3 Mapping'!$A$2:$A$154,A14,'CIS IG3 Mapping'!$H$2:$H$154,"✓") -> 7 | F14: =COUNTIFS('CIS IG3 Mapping'!$A$2:$A$154,A14,'CIS IG3 Mapping'!$J$2:$J$154,"Native") -> 7 | G14: =COUNTIFS('CIS IG3 Mapping'!$A$2:$A$154,A14,'CIS IG3 Mapping'!$J$2:$J$154,"Partial") -> 0 | H14: =COUNTIFS('CIS IG3 Mapping'!$A$2:$A$154,A14,'CIS IG3 Mapping'!$J$2:$J$154,"Process") -> 0 | I14: =COUNTIFS('CIS IG3 Mapping'!$A$2:$A$154,A14,'CIS IG3 Mapping'!$P$2:$P$154,"Implemented") -> 0 | J14: =COUNTIFS('CIS IG3 Mapping'!$A$2:$A$154,A14,'CIS IG3 Mapping'!$P$2:$P$154,"In progress")+COUNTIFS('CIS IG3 Mapping'!$A$2:$A$154,A14,'CIS IG3 Mapping'!$P$2:$P$154,"Planned") -> 0 | K14: =COUNTIFS('CIS IG3 Mapping'!$A$2:$A$154,A14,'CIS IG3 Mapping'!$P$2:$P$154,"Not started")+COUNTIFS('CIS IG3 Mapping'!$A$2:$A$154,A14,'CIS IG3 Mapping'!$P$2:$P$154,"") -> 7 | L14: =IF((C14-COUNTIFS('CIS IG3 Mapping'!$A$2:$A$154,A14,'CIS IG3 Mapping'!$P$2:$P$154,"Not applicable"))=0,0,I14/(C14-COUNTIFS('CIS IG3 Mapping'!$A$2:$A$154,A14,'CIS IG3 Mapping'!$P$2:$P$154,"Not applicable"))) -> 0
A15: 11 | B15: Data Recovery | C15: =COUNTIF('CIS IG3 Mapping'!$A$2:$A$154,A15) -> 5 | D15: =COUNTIFS('CIS IG3 Mapping'!$A$2:$A$154,A15,'CIS IG3 Mapping'!$G$2:$G$154,"✓") -> 4 | E15: =COUNTIFS('CIS IG3 Mapping'!$A$2:$A$154,A15,'CIS IG3 Mapping'!$H$2:$H$154,"✓") -> 5 | F15: =COUNTIFS('CIS IG3 Mapping'!$A$2:$A$154,A15,'CIS IG3 Mapping'!$J$2:$J$154,"Native") -> 4 | G15: =COUNTIFS('CIS IG3 Mapping'!$A$2:$A$154,A15,'CIS IG3 Mapping'!$J$2:$J$154,"Partial") -> 0 | H15: =COUNTIFS('CIS IG3 Mapping'!$A$2:$A$154,A15,'CIS IG3 Mapping'!$J$2:$J$154,"Process") -> 1 | I15: =COUNTIFS('CIS IG3 Mapping'!$A$2:$A$154,A15,'CIS IG3 Mapping'!$P$2:$P$154,"Implemented") -> 0 | J15: =COUNTIFS('CIS IG3 Mapping'!$A$2:$A$154,A15,'CIS IG3 Mapping'!$P$2:$P$154,"In progress")+COUNTIFS('CIS IG3 Mapping'!$A$2:$A$154,A15,'CIS IG3 Mapping'!$P$2:$P$154,"Planned") -> 0 | K15: =COUNTIFS('CIS IG3 Mapping'!$A$2:$A$154,A15,'CIS IG3 Mapping'!$P$2:$P$154,"Not started")+COUNTIFS('CIS IG3 Mapping'!$A$2:$A$154,A15,'CIS IG3 Mapping'!$P$2:$P$154,"") -> 5 | L15: =IF((C15-COUNTIFS('CIS IG3 Mapping'!$A$2:$A$154,A15,'CIS IG3 Mapping'!$P$2:$P$154,"Not applicable"))=0,0,I15/(C15-COUNTIFS('CIS IG3 Mapping'!$A$2:$A$154,A15,'CIS IG3 Mapping'!$P$2:$P$154,"Not applicable"))) -> 0
A16: 12 | B16: Network Infrastructure Management | C16: =COUNTIF('CIS IG3 Mapping'!$A$2:$A$154,A16) -> 8 | D16: =COUNTIFS('CIS IG3 Mapping'!$A$2:$A$154,A16,'CIS IG3 Mapping'!$G$2:$G$154,"✓") -> 1 | E16: =COUNTIFS('CIS IG3 Mapping'!$A$2:$A$154,A16,'CIS IG3 Mapping'!$H$2:$H$154,"✓") -> 7 | F16: =COUNTIFS('CIS IG3 Mapping'!$A$2:$A$154,A16,'CIS IG3 Mapping'!$J$2:$J$154,"Native") -> 6 | G16: =COUNTIFS('CIS IG3 Mapping'!$A$2:$A$154,A16,'CIS IG3 Mapping'!$J$2:$J$154,"Partial") -> 2 | H16: =COUNTIFS('CIS IG3 Mapping'!$A$2:$A$154,A16,'CIS IG3 Mapping'!$J$2:$J$154,"Process") -> 0 | I16: =COUNTIFS('CIS IG3 Mapping'!$A$2:$A$154,A16,'CIS IG3 Mapping'!$P$2:$P$154,"Implemented") -> 0 | J16: =COUNTIFS('CIS IG3 Mapping'!$A$2:$A$154,A16,'CIS IG3 Mapping'!$P$2:$P$154,"In progress")+COUNTIFS('CIS IG3 Mapping'!$A$2:$A$154,A16,'CIS IG3 Mapping'!$P$2:$P$154,"Planned") -> 0 | K16: =COUNTIFS('CIS IG3 Mapping'!$A$2:$A$154,A16,'CIS IG3 Mapping'!$P$2:$P$154,"Not started")+COUNTIFS('CIS IG3 Mapping'!$A$2:$A$154,A16,'CIS IG3 Mapping'!$P$2:$P$154,"") -> 8 | L16: =IF((C16-COUNTIFS('CIS IG3 Mapping'!$A$2:$A$154,A16,'CIS IG3 Mapping'!$P$2:$P$154,"Not applicable"))=0,0,I16/(C16-COUNTIFS('CIS IG3 Mapping'!$A$2:$A$154,A16,'CIS IG3 Mapping'!$P$2:$P$154,"Not applicable"))) -> 0
... A22: 18 | B22: Penetration Testing | C22: =COUNTIF('CIS IG3 Mapping'!$A$2:$A$154,A22) -> 5 | D22: =COUNTIFS('CIS IG3 Mapping'!$A$2:$A$154,A22,'CIS IG3 Mapping'!$G$2:$G$154,"✓") -> 0 | E22: =COUNTIFS('CIS IG3 Mapping'!$A$2:$A$154,A22,'CIS IG3 Mapping'!$H$2:$H$154,"✓") -> 3 | F22: =COUNTIFS('CIS IG3 Mapping'!$A$2:$A$154,A22,'CIS IG3 Mapping'!$J$2:$J$154,"Native") -> 2 | G22: =COUNTIFS('CIS IG3 Mapping'!$A$2:$A$154,A22,'CIS IG3 Mapping'!$J$2:$J$154,"Partial") -> 2 | H22: =COUNTIFS('CIS IG3 Mapping'!$A$2:$A$154,A22,'CIS IG3 Mapping'!$J$2:$J$154,"Process") -> 1 | I22: =COUNTIFS('CIS IG3 Mapping'!$A$2:$A$154,A22,'CIS IG3 Mapping'!$P$2:$P$154,"Implemented") -> 0 | J22: =COUNTIFS('CIS IG3 Mapping'!$A$2:$A$154,A22,'CIS IG3 Mapping'!$P$2:$P$154,"In progress")+COUNTIFS('CIS IG3 Mapping'!$A$2:$A$154,A22,'CIS IG3 Mapping'!$P$2:$P$154,"Planned") -> 0 | K22: =COUNTIFS('CIS IG3 Mapping'!$A$2:$A$154,A22,'CIS IG3 Mapping'!$P$2:$P$154,"Not started")+COUNTIFS('CIS IG3 Mapping'!$A$2:$A$154,A22,'CIS IG3 Mapping'!$P$2:$P$154,"") -> 5 | L22: =IF((C22-COUNTIFS('CIS IG3 Mapping'!$A$2:$A$154,A22,'CIS IG3 Mapping'!$P$2:$P$154,"Not applicable"))=0,0,I22/(C22-COUNTIFS('CIS IG3 Mapping'!$A$2:$A$154,A22,'CIS IG3 Mapping'!$P$2:$P$154,"Not applicable"))) -> 0
B23: Total | C23: =SUM(C5:C22) -> 153 | D23: =SUM(D5:D22) -> 56 | E23: =SUM(E5:E22) -> 130 | F23: =SUM(F5:F22) -> 108 | G23: =SUM(G5:G22) -> 29 | H23: =SUM(H5:H22) -> 16 | I23: =SUM(I5:I22) -> 0 | J23: =SUM(J5:J22) -> 0 | K23: =SUM(K5:K22) -> 153 | L23: =IF((C23-COUNTIF('CIS IG3 Mapping'!$P$2:$P$154,"Not applicable"))=0,0,I23/(C23-COUNTIF('CIS IG3 Mapping'!$P$2:$P$154,"Not applicable"))) -> 0
A25: % Implemented excludes safeguards marked 'Not applicable'. Coverage ratings: see 'Read Me'.

Sheet CIS IG3 Mapping
A1: Control | B1: Control Title | C1: Safeguard | D1: Safeguard Title | E1: Asset Type | F1: Security Function | G1: IG1 | H1: IG2 | I1: IG3 | J1: Microsoft Coverage | K1: Microsoft / Azure / M365 Services | L1: What to Implement to be Compliant | M1: Evidence for Audit | N1: Licensing Notes | O1: Related MCSB | P1: Status | Q1: Owner | R1: Target Date | S1: Notes
A2: 1 | B2: Inventory and Control of Enterprise Assets | C2: 1.1 | D2: Establish and Maintain a Detailed Enterprise Asset Inventory | E2: Devices | F2: Identify | G2: ✓ | H2: ✓ | I2: ✓ | J2: Native | K2: Intune; Defender for Endpoint (device inventory); Entra ID devices; Azure Resource Graph; Defender for Cloud; Azure Arc | L2: Enrol all Windows/macOS/iOS/Android devices in Intune (Autopilot / auto-enrolment via Entra join). Onboard every endpoint and server to Defender for Endpoint so the Device inventory is authoritative. Onboard on-prem/other-cloud servers via Azure Arc so they appear in Azure Resource Graph. Use tags/device categories for owner, department and criticality. Export Intune + MDE + Resource Graph inventories on a schedule (Graph API / Logic App) into a single register and review at least twice a year. | M2: Intune 'All devices' export; MDE Device inventory; Resource Graph query of all resources; review sign-off record. | N2: Intune (M365 E3/E5 or EMS); MDE P2 for full inventory; Azure Arc free for inventory, paid for extra services. | O2: AM-1
A3: 1 | B3: Inventory and Control of Enterprise Assets | C3: 1.2 | D3: Address Unauthorized Assets | E3: Devices | F3: Respond | G3: ✓ | H3: ✓ | I3: ✓ | J3: Native | K3: Intune compliance policies; Entra Conditional Access; Defender for Endpoint (device discovery, 'unmanaged' status); Network Access Control (3rd party) | L3: Require 'device marked compliant' / 'Entra hybrid joined' in Conditional Access so unmanaged devices cannot reach M365/Azure resources. Review MDE Device inventory 'Onboarding status: Can be onboarded / Unsupported' weekly and either onboard, isolate or remove. Use Intune device clean-up rules to retire stale records. Document the weekly review and disposition (remove/deny/quarantine). | M3: Conditional Access policy export; weekly MDE discovered-device review log; Intune device clean-up rule settings. | N3: Entra ID P1 for Conditional Access; MDE P2. | O3: AM-1, NS-1
A4: 1 | B4: Inventory and Control of Enterprise Assets | C4: 1.3 | D4: Utilize an Active Discovery Tool | E4: Devices | F4: Detect | H4: ✓ | I4: ✓ | J4: Native | K4: Defender for Endpoint device discovery (Standard/active probing); Defender for IoT; Defender External Attack Surface Management | L4: Set MDE Device discovery mode to 'Standard discovery' so onboarded devices actively probe the network. Configure monitored networks and exclusions in Settings > Device discovery. Use Defender for IoT for OT/IoT segments and Defender EASM for internet-facing assets. Run discovery at least daily; feed new findings into the 1.2 process. | M4: MDE Device discovery settings screenshot; discovered-device report; EASM inventory. | N4: MDE P2 / Defender for Business; Defender for IoT and EASM licensed separately. | O4: AM-1
A5: 1 | B5: Inventory and Control of Enterprise Assets | C5: 1.4 | D5: Use DHCP Logging to Update Enterprise Asset Inventory | E5: Devices | F5: Identify | H5: ✓ | I5: ✓ | J5: Partial | K5: Windows Server DHCP audit logs; Azure Monitor Agent + Data Collection Rules; Microsoft Sentinel; (Azure VNets use platform DHCP with no customer logs) | L5: Enable DHCP audit logging on Windows DHCP servers (or your network DHCP appliance). Collect the logs with Azure Monitor Agent / syslog connector into Sentinel. Build a scheduled KQL query that lists MAC/IP/hostname leases not present in the MDE/Intune inventory and raise an incident or update the asset register weekly. In Azure, use NIC/VM inventory from Resource Graph instead because Azure DHCP is platform-managed. | M5: DCR config; Sentinel analytics rule 'DHCP lease not in inventory'; weekly results. | N5: Sentinel / Log Analytics ingestion cost. | O5: AM-1, LT-1
A6: 1 | B6: Inventory and Control of Enterprise Assets | C6: 1.5 | D6: Use a Passive Asset Discovery Tool | E6: Devices | F6: Detect | I6: ✓ | J6: Native | K6: Defender for Endpoint (Basic/passive discovery); Defender for IoT network sensors; Defender for Identity | L6: Keep MDE passive discovery enabled (it is on by default with Standard mode). Deploy Defender for IoT sensors on SPAN/TAP ports in OT, IoT and data-centre segments for passive fingerprinting. Defender for Identity sensors on domain controllers add passive identification of devices authenticating to AD. Review newly discovered assets weekly and update the inventory. | M6: Defender for IoT sensor list and device inventory; MDE discovered devices with 'Discovery source' passive. | N6: MDE P2; Defender for IoT (per-site licence); Defender for Identity (E5 Security). | O6: AM-1, NS-1
A7: 2 | B7: Inventory and Control of Software Assets | C7: 2.1 | D7: Establish and Maintain a Software Inventory | E7: Software | F7: Identify | G7: ✓ | H7: ✓ | I7: ✓ | J7: Native | K7: Defender Vulnerability Management (Software inventory); Intune Discovered apps; Azure Arc / Defender for Servers; Configuration Manager | L7: Use MDE/Defender Vulnerability Management Software inventory as the system of record (publisher, version, install count, end-of-support). Supplement with Intune 'Discovered apps' and Intune app catalogue for business purpose/owner. For servers, onboard Defender for Servers via Arc. Export via Graph/Advanced Hunting (DeviceTvmSoftwareInventory) and add business owner, purpose, approval status. Review every six months. | M7: DVM software inventory export; approved software register with owners and review date. | N7: MDE P2 includes core TVM; DVM add-on / Defender for Servers P2 for full features. | O7: AM-2, AM-5
A8: 2 | B8: Inventory and Control of Software Assets | C8: 2.2 | D8: Ensure Authorized Software is Currently Supported | E8: Software | F8: Identify | G8: ✓ | H8: ✓ | I8: ✓ | J8: Native | K8: Defender Vulnerability Management (end-of-support software & versions); Intune; Azure Advisor / Defender for Cloud | L8: Use DVM 'End of support' filter and the 'Upgrade' security recommendations to identify unsupported apps/OS. Track Windows/Office servicing channels in Intune (Windows Update rings, feature update policies, M365 Apps update channel). Record documented exceptions with compensating controls for anything unsupported that must remain. Review monthly. | M8: DVM EOS report; exception register with compensating controls. | N8: MDE P2 / DVM add-on. | O8: AM-2, PV-6
A9: 2 | B9: Inventory and Control of Software Assets | C9: 2.3 | D9: Address Unauthorized Software | E9: Software | F9: Respond | G9: ✓ | H9: ✓ | I9: ✓ | J9: Native | K9: Defender Vulnerability Management (block vulnerable apps / remediation requests); Intune (uninstall assignments); App Control for Business; Defender for Cloud Apps | L9: Review the software inventory monthly against the approved list. Remove unauthorized software using Intune uninstall assignments or Win32 app with uninstall command, or create DVM remediation requests. Block it from running with App Control for Business / MDE indicators (file hash / certificate). For SaaS, mark unsanctioned apps in Defender for Cloud Apps to block via MDE network protection. | M9: Monthly unauthorized-software review; Intune uninstall assignments; MDE file/cert indicators; MDCA unsanctioned apps list. | N9: MDE P2; Intune; Defender for Cloud Apps (E5). | O9: AM-5
A10: 2 | B10: Inventory and Control of Software Assets | C10: 2.4 | D10: Utilize Automated Software Inventory Tools | E10: Software | F10: Detect | H10: ✓ | I10: ✓ | J10: Native | K10: Defender for Endpoint / DVM; Intune Discovered apps; Defender for Servers (Arc); Azure Update Manager / Change Tracking & Inventory | L10: Ensure 100% of endpoints and servers are onboarded to MDE (sensor collects software inventory continuously). Enable Change Tracking and Inventory on Azure/Arc servers for installed software and service changes. Use Advanced Hunting/Graph to automate the inventory export for 2.1. | M10: Onboarding coverage report (% devices onboarded); Change Tracking workspace data. | N10: MDE P2; Defender for Servers; Log Analytics ingestion. | O10: AM-2
A11: 2 | B11: Inventory and Control of Software Assets | C11: 2.5 | D11: Allowlist Authorized Software | E11: Software | F11: Protect | H11: ✓ | I11: ✓ | J11: Native | K11: App Control for Business (WDAC) via Intune incl. Managed Installer and ISG; AppLocker; Defender for Cloud adaptive application controls (retired - use WDAC); Intune Endpoint Privilege Management | L11: Deploy App Control for Business policies through Intune: start in audit mode, set Intune Management Extension as Managed Installer, optionally trust Intelligent Security Graph, then enforce. Use supplemental policies for line-of-business apps signed with your certificate. Pair with standard-user accounts and Intune Endpoint Privilege Management so users cannot install unapproved software. Review policy at least twice a year. | M11: Intune App Control policy (enforced); CodeIntegrity event logs / Advanced Hunting DeviceEvents AppControl*; review records. | N11: Windows Enterprise/Education (E3+) for App Control; EPM needs Intune Suite/add-on. | O11: AM-5, ES-2
A12: 2 | B12: Inventory and Control of Software Assets | C12: 2.6 | D12: Allowlist Authorized Libraries | E12: Software | F12: Protect | H12: ✓ | I12: ✓ | J12: Native | K12: App Control for Business (DLL enforcement); AppLocker DLL rules | L12: Enable DLL/driver enforcement in App Control for Business policies (it covers .dll and .sys files when 'Disabled: Script Enforcement' not set and kernel/user mode rules defined). Allow libraries by publisher signer or hash; test in audit mode before enforcement. For servers, use the same policies via Arc/GPO. | M12: App Control policy XML showing user-mode code integrity & signer rules; audit/enforce event logs. | N12: Windows Enterprise / Server. | O12: AM-5, ES-2
A13: 2 | B13: Inventory and Control of Software Assets | C13: 2.7 | D13: Allowlist Authorized Scripts | E13: Software | F13: Protect | I13: ✓ | J13: Native | K13: App Control for Business script enforcement (PowerShell Constrained Language Mode); Intune script signing; AMSI; ASR rules | L13: Enable script enforcement in App Control so unsigned PowerShell runs in Constrained Language Mode and unapproved .js/.vbs/.ps1 are blocked. Sign approved scripts with an internal code-signing cert and set PowerShell execution policy AllSigned via Intune. Add ASR rules 'Block execution of potentially obfuscated scripts' and 'Block JavaScript or VBScript from launching downloaded executable content'. Keep AMSI enabled. | M13: App Control policy with script enforcement; Intune PowerShell execution policy; ASR rule report. | N13: Windows Enterprise; MDE for ASR reporting. | O13: AM-5, ES-2
A14: 3 | B14: Data Protection | C14: 3.1 | D14: Establish and Maintain a Data Management Process | E14: Data | F14: Govern | G14: ✓ | H14: ✓ | I14: ✓ | J14: Process | K14: Microsoft Purview (Compliance Manager, Information Protection, Data Lifecycle Management); SharePoint policy library | L14: Write and approve a data management policy covering data sensitivity, owners, handling, retention and disposal. Implement it technically through Purview sensitivity labels (3.7), retention policies (3.4) and DLP (3.13). Track the policy as evidence in Compliance Manager and review annually or on significant change. | M14: Approved data management policy; Compliance Manager evidence; annual review record. | N14: Purview features vary by E3/E5. | O14: DP-1, GS-4
A15: 3 | B15: Data Protection | C15: 3.2 | D15: Establish and Maintain a Data Inventory | E15: Data | F15: Identify | G15: ✓ | H15: ✓ | I15: ✓ | J15: Native | K15: Microsoft Purview Data Map / Unified Catalog; Purview Content Explorer & Data Explorer; Defender for Cloud (sensitive data discovery); Data Security Posture Management | L15: Use Purview Content Explorer to inventory sensitive information types and labels across Exchange, SharePoint, OneDrive and Teams. Register Azure data sources (SQL, Storage, Synapse, Fabric) and on-prem sources in Purview Data Map and run classification scans. Enable Defender CSPM sensitive data discovery for storage/databases. Record owners and sensitivity; review annually (prioritise sensitive data). | M15: Purview Data Map scan results; Content Explorer report; data owner register. | N15: Content Explorer needs E5 Compliance; Data Map is pay-as-you-go; Defender CSPM plan. | O15: DP-1
A16: 3 | B16: Data Protection | C16: 3.3 | D16: Configure Data Access Control Lists | E16: Data | F16: Protect | G16: ✓ | H16: ✓ | I16: ✓ | J16: Native | K16: SharePoint/OneDrive permissions & sharing settings; Entra groups; Azure RBAC; Storage/SQL Entra authentication; SharePoint Advanced Management (site access reviews); Entra Access Reviews | L16: Restrict tenant and site-level external sharing; default sharing links to 'Specific people'. Grant access via Entra security groups, not individuals. Use Azure RBAC and Entra-only authentication for Storage, SQL and Key Vault (disable shared keys / SQL auth where possible). Run Entra access reviews on groups/Teams that grant access to sensitive data and SharePoint Advanced Management data access governance reports for overshared sites. | M16: Sharing settings export; RBAC assignments; access review results; oversharing reports. | N16: Access Reviews need Entra ID P2/Governance; SharePoint Advanced Management add-on (included with Copilot). | O16: DP-1, PA-7, IM-1
A17: 3 | B17: Data Protection | C17: 3.4 | D17: Enforce Data Retention | E17: Data | F17: Protect | G17: ✓ | H17: ✓ | I17: ✓ | J17: Native | K17: Purview Data Lifecycle Management / Records Management (retention policies & labels); Azure Storage lifecycle management; Azure SQL long-term retention | L17: Create Purview retention policies per workload (Exchange, SharePoint, OneDrive, Teams) that keep and then delete data per the retention schedule. Use retention labels (auto-apply on SITs/trainable classifiers in E5) for records with specific periods. For Azure data, use Storage lifecycle policies and immutable storage where required. Document minimum and maximum timelines per data class. | M17: Retention policy list and scope; retention schedule document; lifecycle rules. | N17: Basic retention in E3; auto-apply labels and Records Management in E5 Compliance. | O17: DP-1
A18: 3 | B18: Data Protection | C18: 3.5 | D18: Securely Dispose of Data | E18: Data | F18: Protect | G18: ✓ | H18: ✓ | I18: ✓ | J18: Partial | K18: Purview disposition reviews / retention delete; Intune Wipe / Autopilot Reset; BitLocker (crypto-erase); Azure Storage deletion (platform sanitisation) | L18: Use Purview retention with 'delete at end of period' and disposition reviews for records, with proof-of-disposition. Wipe devices with Intune Wipe before reassignment/disposal; BitLocker ensures data is unrecoverable once keys are removed. Microsoft sanitises Azure/M365 media per its NIST 800-88 process (see Service Trust Portal). Use a certified vendor for physical media destruction. | M18: Disposition review records; Intune wipe audit log; destruction certificates; Microsoft STP data-destruction documentation. | N18: Disposition reviews need E5 Compliance / Records Management. | O18: DP-1, AM-1
A19: 3 | B19: Data Protection | C19: 3.6 | D19: Encrypt Data on End-User Devices | E19: Devices | F19: Protect | G19: ✓ | H19: ✓ | I19: ✓ | J19: Native | K19: Intune Endpoint security > Disk encryption (BitLocker, FileVault); Intune compliance policies; iOS/Android native encryption | L19: Deploy Intune BitLocker policy (XTS-AES 256, silent encryption, TPM protector, recovery keys escrowed to Entra ID) and FileVault policy for macOS (keys escrowed to Intune). Require encryption in compliance policies and enforce via Conditional Access. Mobile devices: require device encryption/passcode in compliance policy. | M19: Intune encryption report; compliance policy; Conditional Access requiring compliant device. | N19: Intune; Windows Pro+ for BitLocker. | O19: DP-5, ES-3
A20: 3 | B20: Data Protection | C20: 3.7 | D20: Establish and Maintain a Data Classification Scheme | E20: Data | F20: Govern | H20: ✓ | I20: ✓ | J20: Native | K20: Microsoft Purview Information Protection (sensitivity labels, label policies, default labels); sensitive information types; trainable classifiers | L20: Define a classification scheme (e.g. Public / Internal / Confidential / Highly Confidential) and implement it as Purview sensitivity labels with encryption, marking and container (Teams/SharePoint) settings. Publish label policies with mandatory labelling and default labels. Enable auto-labelling for SITs (client-side in E3 apps; service-side in E5). Review annually. | M20: Label taxonomy document; label & policy configuration; label usage in Activity Explorer. | N20: Manual labels in E3; auto-labelling & Activity Explorer in E5 Compliance. | O20: DP-1
A21: 3 | B21: Data Protection | C21: 3.8 | D21: Document Data Flows | E21: Data | F21: Identify | H21: ✓ | I21: ✓ | J21: Partial | K21: Purview Data Map lineage; Azure Data Factory/Fabric lineage; Visio/Whiteboard; Defender CSPM attack-path / data-sensitivity insights | L21: Document flows of sensitive data between systems, including service providers. Use Purview lineage for ADF/Synapse/Fabric pipelines and Defender CSPM data sensitivity map for cloud stores. Maintain data flow diagrams in a controlled SharePoint library and review annually or on major change. | M21: Data flow diagrams with version history; Purview lineage views. | N21: Purview Data Map consumption; Defender CSPM. | O21: DP-1, GS-3
A22: 3 | B22: Data Protection | C22: 3.9 | D22: Encrypt Data on Removable Media | E22: Data | F22: Protect | H22: ✓ | I22: ✓ | J22: Native | K22: Intune BitLocker policy (Deny write access to removable drives not protected by BitLocker / BitLocker To Go); Defender device control | L22: In Intune BitLocker settings enable 'Deny write access to removable drives not protected by BitLocker' and require BitLocker To Go with AES-256. Combine with Defender Device Control to allow only approved encrypted USB models. Apply Purview Endpoint DLP to block copying sensitive data to USB. | M22: Intune BitLocker removable drive settings; Device Control policy; Endpoint DLP rules. | N22: Windows Enterprise; MDE; Endpoint DLP needs E5 Compliance. | O22: DP-5, ES-3
A23: 3 | B23: Data Protection | C23: 3.10 | D23: Encrypt Sensitive Data in Transit | E23: Data | F23: Protect | H23: ✓ | I23: ✓ | J23: Native | K23: M365 TLS 1.2+ (default); Exchange TLS / MTA-STS / connectors with forced TLS; Azure Policy (HTTPS only, minimum TLS 1.2 on Storage, App Service, SQL); Azure VPN Gateway / ExpressRoute MACsec; Purview Message Encryption | L23: Use Azure Policy built-ins to enforce 'Secure transfer to storage accounts', 'Minimum TLS version 1.2', 'App Service should only be accessible over HTTPS' and 'Function apps HTTPS only'. Configure Exchange Online inbound/outbound connectors with mandatory TLS for partners and publish MTA-STS. Use Purview Message Encryption / sensitivity labels for sensitive email. Disable legacy protocols (SMBv1, TLS 1.0/1.1) via Intune/GPO. | M23: Azure Policy compliance report; Exchange connector config; Intune protocol hardening profiles. | N23: Azure Policy free; Purview Message Encryption in E3 (Advanced in E5). | O23: DP-3
A24: 3 | B24: Data Protection | C24: 3.11 | D24: Encrypt Sensitive Data at Rest | E24: Data | F24: Protect | H24: ✓ | I24: ✓ | J24: Native | K24: Azure Storage/SQL TDE/Disk encryption (platform, CMK via Key Vault); Azure Disk Encryption / encryption at host; M365 Customer Key; Purview sensitivity labels with encryption; Key Vault / Managed HSM | L24: Azure: platform encryption is on by default; for sensitive data use customer-managed keys in Key Vault/Managed HSM and enforce via Azure Policy (CMK, encryption at host, TDE). M365: data is encrypted at rest by default; consider Customer Key for tenant-held keys. Add application-layer encryption via sensitivity labels (Rights Management) for highly sensitive files. Protect keys with RBAC, purge protection and rotation. | M24: Azure Policy CMK compliance; Key Vault configuration; label encryption settings. | N24: Customer Key needs E5 Compliance; Key Vault/Managed HSM consumption. | O24: DP-4, DP-5, DP-6
A25: 3 | B25: Data Protection | C25: 3.12 | D25: Segment Data Processing and Storage Based on Sensitivity | E25: Network | F25: Protect | H25: ✓ | I25: ✓ | J25: Native | K25: Azure landing zones (management groups, subscriptions); VNets/NSGs/Private Endpoints; Azure Firewall; SharePoint sensitivity-labelled sites; Information Barriers; Purview Administrative Units | L25: Place sensitive workloads in dedicated subscriptions / VNets with private endpoints and no public network access (enforce with Azure Policy). Segment with NSGs and Azure Firewall. In M365, keep highly confidential data in labelled Teams/SharePoint sites with restricted membership, block guest access and use Restricted Access Control. Do not process sensitive data on assets of lower classification. | M25: Landing zone design; Azure Policy 'public network access disabled'; site/label settings. | N25: Azure Firewall/Private Link consumption; Information Barriers in E5. | O25: NS-1, NS-2, DP-1
A26: 3 | B26: Data Protection | C26: 3.13 | D26: Deploy a Data Loss Prevention Solution | E26: Data | F26: Protect | I26: ✓ | J26: Native | K26: Microsoft Purview DLP (Exchange, SharePoint, OneDrive, Teams, Endpoint, Copilot, on-prem scanner); Defender for Cloud Apps; Edge for Business DLP | L26: Deploy Purview DLP policies for each location using sensitive info types, trainable classifiers and sensitivity labels; start in simulation then enforce with block/override. Enable Endpoint DLP (USB, print, cloud upload, clipboard, unallowed apps/browsers). Use Defender for Cloud Apps session policies to control downloads from unmanaged devices. Deploy the Purview information protection scanner for on-prem file shares. Review DLP alerts in Defender XDR. | M26: DLP policy list (enforced); DLP alerts and Activity Explorer; scanner reports. | N26: Exchange/SPO/OD DLP in E3; Teams, Endpoint DLP & advanced in E5 Compliance. | O26: DP-2
A27: 3 | B27: Data Protection | C27: 3.14 | D27: Log Sensitive Data Access | E27: Data | F27: Detect | I27: ✓ | J27: Native | K27: Purview Audit (Standard/Premium), Activity Explorer; Azure Storage/SQL diagnostic logs; Sentinel; Defender for Cloud Apps | L27: Ensure Purview unified audit logging is on (default) and use Audit Premium for MailItemsAccessed and longer retention. Enable diagnostic logging for Storage (read operations), SQL auditing, Key Vault and Cosmos DB, sending to Log Analytics/Sentinel. Build Sentinel/Insider Risk alerts for mass download or access to Highly Confidential labels. | M27: Audit configuration; diagnostic setting policy compliance; sample audit search for labelled files. | N27: Audit Premium in E5; Sentinel/Log Analytics ingestion. | O27: DP-2, LT-4
A28: 4 | B28: Secure Configuration of Enterprise Assets and Software | C28: 4.1 | D28: Establish and Maintain a Secure Configuration Process | E28: Documentation | F28: Govern | G28: ✓ | H28: ✓ | I28: ✓ | J28: Native | K28: Intune security baselines & Settings catalog; Microsoft Security Compliance Toolkit; Azure Policy & Machine Configuration; Defender for Cloud secure score; Defender Vulnerability Management security baseline assessments | L28: Adopt documented baselines (e.g. CIS Benchmarks / Microsoft security baselines / OpenIntuneBaseline) for Windows, macOS, mobile, servers and M365. Deploy them through Intune security baselines/Settings catalog and, for servers, Azure Machine Configuration or GPO. Measure drift with DVM security baseline assessments (CIS/STIG profiles) and Defender for Cloud. Review annually. | M28: Baseline documents; Intune profile assignments; DVM baseline compliance %; secure score history. | N28: DVM baselines need DVM add-on / MDE P2+; Defender for Servers P2 for Machine Configuration. | O28: PV-1, PV-2, PV-3
A29: 4 | B29: Secure Configuration of Enterprise Assets and Software | C29: 4.2 | D29: Establish and Maintain a Secure Configuration Process for Network Infrastructure | E29: Network | F29: Govern | G29: ✓ | H29: ✓ | I29: ✓ | J29: Partial | K29: Azure Policy (NSG, Firewall, App Gateway, Front Door); Azure Firewall Manager policies; Defender CSPM; Network vendor tooling for physical devices | L29: Define secure configuration standards for Azure network services (Azure Policy initiatives for NSGs, WAF enabled, DDoS, no public IP on management ports) and manage Azure Firewall rules centrally via Firewall Manager. For physical switches/firewalls/Wi-Fi use vendor CIS benchmarks and config management. Review annually. | M29: Network configuration standard; Azure Policy compliance; firewall policy versions. | N29: Azure Policy free; Defender CSPM plan. | O29: NS-1, PV-1
A30: 4 | B30: Secure Configuration of Enterprise Assets and Software | C30: 4.3 | D30: Configure Automatic Session Locking on Enterprise Assets | E30: Devices | F30: Protect | G30: ✓ | H30: ✓ | I30: ✓ | J30: Native | K30: Intune Settings catalog (Interactive logon: machine inactivity limit, screen saver); macOS screen lock; mobile passcode policies; Entra Conditional Access sign-in frequency | L30: Set 'Interactive logon: Machine inactivity limit' to 900 seconds or less on Windows (15 min general purpose, 2 min mobile per CIS), macOS screensaver/password delay via Intune, and maximum inactivity before lock on iOS/Android. Use Conditional Access session controls / app idle timeout for browser sessions on unmanaged devices. | M30: Intune configuration profiles and compliance status. | N30: Intune. | O30: ES-2, PV-4
A31: 4 | B31: Secure Configuration of Enterprise Assets and Software | C31: 4.4 | D31: Implement and Manage a Firewall on Servers | E31: Devices | F31: Protect | G31: ✓ | H31: ✓ | I31: ✓ | J31: Native | K31: Windows Defender Firewall via Intune/GPO/Machine Configuration; Azure NSGs & ASGs; Azure Firewall; Defender for Cloud (JIT VM access, NSG hardening recommendations) | L31: Enable Windows Firewall on all profiles with default-deny inbound on servers (Intune/GPO/Azure Machine Configuration). Apply NSGs on every subnet/NIC with least-privilege rules; use Azure Firewall for egress. Enable Defender for Cloud Just-In-Time VM access to close management ports. Review rule sets periodically. | M31: Firewall policy; NSG rule exports; Defender for Cloud recommendation status. | N31: JIT needs Defender for Servers P2. | O31: NS-1, NS-2, ES-2
A32: 4 | B32: Secure Configuration of Enterprise Assets and Software | C32: 4.5 | D32: Implement and Manage a Firewall on End-User Devices | E32: Devices | F32: Protect | G32: ✓ | H32: ✓ | I32: ✓ | J32: Native | K32: Intune Endpoint security > Firewall (Windows), macOS firewall; Firewall rules; MDE network protection | L32: Deploy Intune Firewall policy: all profiles on, default inbound block, outbound allow, block local rule merging for public profile. Enable macOS application firewall + stealth mode. Restrict inbound rules to required management ports only. | M32: Intune firewall policy & device status report. | N32: Intune. | O32: ES-2, NS-1
A33: 4 | B33: Secure Configuration of Enterprise Assets and Software | C33: 4.6 | D33: Securely Manage Enterprise Assets and Software | E33: Devices | F33: Protect | G33: ✓ | H33: ✓ | I33: ✓ | J33: Native | K33: Intune (config-as-code via Graph); Azure Bastion; Azure Policy; Windows LAPS; Infrastructure as Code (Bicep/Terraform) in Azure DevOps/GitHub; Privileged Access Workstations | L33: Manage endpoints via Intune (version-controlled configuration, e.g. exported with IntuneManagement/Graph). Manage Azure via IaC pipelines with approvals; use secure protocols only (SSH, HTTPS, RDP via Azure Bastion). Disable insecure management protocols (Telnet, HTTP). Use Windows LAPS for local admin passwords. | M33: IaC repository with PR approvals; Bastion configuration; LAPS policy. | N33: Intune; Bastion consumption. | O33: PV-1, PA-6, NS-1
A34: 4 | B34: Secure Configuration of Enterprise Assets and Software | C34: 4.7 | D34: Manage Default Accounts on Enterprise Assets and Software | E34: Users | F34: Protect | G34: ✓ | H34: ✓ | I34: ✓ | J34: Native | K34: Windows LAPS (Intune Account protection policy); Intune 'Accounts: Rename/disable Administrator and Guest'; Azure VM admin naming policies; Entra 'break-glass' process | L34: Disable the built-in Guest account and rename/disable built-in Administrator via Intune. Use Windows LAPS (Intune) to rotate unique local admin passwords and back up to Entra ID. Change all vendor default credentials on appliances and apps. Azure: prevent default admin names (e.g. 'admin', 'administrator') via policy. | M34: Intune account protection & LAPS policy; LAPS password rotation evidence. | N34: Intune; Windows LAPS built-in. | O34: IM-3, PA-1
A35: 4 | B35: Secure Configuration of Enterprise Assets and Software | C35: 4.8 | D35: Uninstall or Disable Unnecessary Services on Enterprise Assets and Software | E35: Devices | F35: Protect | H35: ✓ | I35: ✓ | J35: Native | K35: Intune Settings catalog (System Services); Intune security baselines; Azure Machine Configuration; Defender Vulnerability Management baselines | L35: Disable unneeded Windows services (e.g. Print Spooler on servers/DCs, Xbox services, Remote Registry, SSDP) via Intune Settings catalog or GPO. Remove optional features (SMBv1, PowerShell v2, Telnet client). Measure with DVM security baseline assessment and Defender for Cloud OS configuration recommendations. | M35: Intune service-config profile; DVM baseline report. | N35: Intune; DVM add-on. | O35: PV-1, ES-2
A36: 4 | B36: Secure Configuration of Enterprise Assets and Software | C36: 4.9 | D36: Configure Trusted DNS Servers on Enterprise Assets | E36: Devices | F36: Protect | H36: ✓ | I36: ✓ | J36: Native | K36: Intune (DNS settings / DoH via Settings catalog); Azure DNS / Azure DNS Private Resolver; Azure Firewall DNS proxy; Microsoft Entra Internet Access | L36: Configure endpoints to use enterprise-controlled DNS (on-prem AD DNS, Azure DNS Private Resolver, or a protective DNS service) and enforce DoH templates via Intune. In Azure, point VNets to Azure Firewall DNS proxy / Private Resolver. Block outbound DNS (UDP/TCP 53, DoH endpoints) to anything else at the firewall. | M36: Intune DNS/DoH profile; VNet DNS settings; firewall rule blocking external DNS. | N36: Azure Firewall/Private Resolver consumption; Entra Internet Access licence. | O36: NS-10
A37: 4 | B37: Secure Configuration of Enterprise Assets and Software | C37: 4.10 | D37: Enforce Automatic Device Lockout on Portable End-User Devices | E37: Devices | F37: Protect | H37: ✓ | I37: ✓ | J37: Native | K37: Intune device restrictions / compliance (max failed sign-ins before wipe); Windows 'Interactive logon: Machine account lockout threshold' with BitLocker; iOS/Android passcode policies | L37: Set maximum failed unlock attempts before wipe (≤10 for phones/tablets, ≤20 for laptops per CIS) using Intune iOS/Android device restrictions and Windows 'Machine account lockout threshold' (requires BitLocker). Enforce through compliance policies. | M37: Intune device restriction profiles. | N37: Intune. | O37: ES-2
A38: 4 | B38: Secure Configuration of Enterprise Assets and Software | C38: 4.11 | D38: Enforce Remote Wipe Capability on Portable End-User Devices | E38: Devices | F38: Protect | H38: ✓ | I38: ✓ | J38: Native | K38: Intune remote actions (Wipe, Retire, Selective wipe of app data via App Protection Policies) | L38: Enrol all portable devices in Intune (or use MAM App Protection Policies for BYOD) so Wipe / Retire / selective wipe can be issued when a device is lost or an employee leaves. Document the lost-device procedure and link it to incident reporting (17.3). | M38: Intune enrolment coverage; remote wipe action log; lost-device procedure. | N38: Intune. | O38: ES-3, AM-1
A39: 4 | B39: Secure Configuration of Enterprise Assets and Software | C39: 4.12 | D39: Separate Enterprise Workspaces on Mobile End-User Devices | E39: Devices | F39: Protect | I39: ✓ | J39: Native | K39: Intune Android Enterprise Work Profile; iOS User Enrollment / managed apps; Intune App Protection Policies (MAM); Windows MAM for Edge | L39: Use Android Enterprise personally-owned work profile and iOS/iPadOS account-driven User Enrollment for BYOD. Apply App Protection Policies to restrict copy/paste and save-as between managed and unmanaged apps, require PIN, encrypt app data. Require approved client apps / app protection via Conditional Access. | M39: Enrolment profiles; App Protection Policy settings; Conditional Access 'require app protection policy'. | N39: Intune; Entra ID P1. | O39: ES-3, DP-2
A40: 5 | B40: Account Management | C40: 5.1 | D40: Establish and Maintain an Inventory of Accounts | E40: Users | F40: Identify | G40: ✓ | H40: ✓ | I40: ✓ | J40: Native | K40: Microsoft Entra ID (users, guests, workload identities); Active Directory; Defender for Identity; Entra ID Governance (lifecycle workflows); Graph API exports | L40: Treat Entra ID (synced from AD/HR) as the account inventory: name, UPN, department, manager, start/end date via HR-driven provisioning (Workday/SuccessFactors) or Entra Connect. Export users, guests and admins quarterly via Graph and validate that all active accounts are authorized. Include local and application accounts not in Entra. | M40: Quarterly account inventory export & validation sign-off. | N40: Entra ID Free/P1; HR provisioning & lifecycle workflows need Entra ID Governance. | O40: IM-1, PA-1
...
